
Training:   0%|                                                  | 0/600000 [04:28<?, ?it/s]
Traceback (most recent call last):
  File "/home/zaydzuhri/fadeformer/train.py", line 197, in <module>
    logits, loss = model(X, Y)
  File "/home/zaydzuhri/.local/lib/python3.10/site-packages/torch/nn/modules/module.py", line 1501, in _call_impl
    return forward_call(*args, **kwargs)
  File "/home/zaydzuhri/fadeformer/models/gpt.py", line 144, in forward
    x = self.blocks(x) # (B, T, C)
  File "/home/zaydzuhri/.local/lib/python3.10/site-packages/torch/nn/modules/module.py", line 1501, in _call_impl
    return forward_call(*args, **kwargs)
  File "/home/zaydzuhri/.local/lib/python3.10/site-packages/torch/nn/modules/container.py", line 217, in forward
    input = module(input)
  File "/home/zaydzuhri/.local/lib/python3.10/site-packages/torch/nn/modules/module.py", line 1501, in _call_impl
    return forward_call(*args, **kwargs)
  File "/home/zaydzuhri/fadeformer/models/gpt.py", line 92, in forward
    out = out + self.ff(self.ln2(out))
  File "/home/zaydzuhri/.local/lib/python3.10/site-packages/torch/nn/modules/module.py", line 1501, in _call_impl
    return forward_call(*args, **kwargs)
  File "/home/zaydzuhri/fadeformer/models/gpt.py", line 75, in forward
    out = self.lin2(out)
  File "/home/zaydzuhri/.local/lib/python3.10/site-packages/torch/nn/modules/module.py", line 1501, in _call_impl
    return forward_call(*args, **kwargs)
  File "/home/zaydzuhri/.local/lib/python3.10/site-packages/torch/nn/modules/linear.py", line 114, in forward
    return F.linear(input, self.weight, self.bias)
RuntimeError: CUDA error: unknown error
CUDA kernel errors might be asynchronously reported at some other API call, so the stacktrace below might be incorrect.
For debugging consider passing CUDA_LAUNCH_BLOCKING=1.
Compile with `TORCH_USE_CUDA_DSA` to enable device-side assertions.
Traceback (most recent call last):
  File "/home/zaydzuhri/fadeformer/train.py", line 197, in <module>
    logits, loss = model(X, Y)
  File "/home/zaydzuhri/.local/lib/python3.10/site-packages/torch/nn/modules/module.py", line 1501, in _call_impl
    return forward_call(*args, **kwargs)
  File "/home/zaydzuhri/fadeformer/models/gpt.py", line 144, in forward
    x = self.blocks(x) # (B, T, C)
  File "/home/zaydzuhri/.local/lib/python3.10/site-packages/torch/nn/modules/module.py", line 1501, in _call_impl
    return forward_call(*args, **kwargs)
  File "/home/zaydzuhri/.local/lib/python3.10/site-packages/torch/nn/modules/container.py", line 217, in forward
    input = module(input)
  File "/home/zaydzuhri/.local/lib/python3.10/site-packages/torch/nn/modules/module.py", line 1501, in _call_impl
    return forward_call(*args, **kwargs)
  File "/home/zaydzuhri/fadeformer/models/gpt.py", line 92, in forward
    out = out + self.ff(self.ln2(out))
  File "/home/zaydzuhri/.local/lib/python3.10/site-packages/torch/nn/modules/module.py", line 1501, in _call_impl
    return forward_call(*args, **kwargs)
  File "/home/zaydzuhri/fadeformer/models/gpt.py", line 75, in forward
    out = self.lin2(out)
  File "/home/zaydzuhri/.local/lib/python3.10/site-packages/torch/nn/modules/module.py", line 1501, in _call_impl
    return forward_call(*args, **kwargs)
  File "/home/zaydzuhri/.local/lib/python3.10/site-packages/torch/nn/modules/linear.py", line 114, in forward
    return F.linear(input, self.weight, self.bias)
RuntimeError: CUDA error: unknown error
CUDA kernel errors might be asynchronously reported at some other API call, so the stacktrace below might be incorrect.
For debugging consider passing CUDA_LAUNCH_BLOCKING=1.
Compile with `TORCH_USE_CUDA_DSA` to enable device-side assertions.
iter 0 | train loss: 10.996561050415039 | val loss: 10.991423606872559 | time: 268.74696040153503